Workbook
Name GP_BY_Sectors: 'Generic Parameters'!$A$260:$A$270
Name GP_BY_T: 'Generic Parameters'!$B$260:$M$270
Name GP_CR_Sectors: 'Generic Parameters'!$A$120:$A$130
Name GP_CR_T: 'Generic Parameters'!$B$120:$M$130
Name GP_CX_Sectors: 'Generic Parameters'!$A$176:$A$186
Name GP_CX_T: 'Generic Parameters'!$B$176:$M$186
Name GP_DY_Sectors: 'Generic Parameters'!$A$232:$A$242
Name GP_DY_T: 'Generic Parameters'!$B$232:$M$242
Name GP_EG_Sectors: 'Generic Parameters'!$A$78:$A$88
Name GP_EG_T: 'Generic Parameters'!$B$78:$M$88
Name GP_EV_Sectors: 'Generic Parameters'!$A$204:$A$214
Name GP_EV_T: 'Generic Parameters'!$B$204:$M$214
Name GP_FM_Sectors: 'Generic Parameters'!$A$148:$A$158
Name GP_FM_T: 'Generic Parameters'!$B$148:$M$158
Name GP_FN_Sectors: 'Generic Parameters'!$A$162:$A$172
Name GP_FN_T: 'Generic Parameters'!$B$162:$M$172
Name GP_IC_Sectors: 'Generic Parameters'!$A$134:$A$144
Name GP_IC_T: 'Generic Parameters'!$B$134:$M$144
Name GP_ND_Sectors: 'Generic Parameters'!$A$106:$A$116
Name GP_ND_T: 'Generic Parameters'!$B$106:$M$116
Name GP_NM_Sectors: 'Generic Parameters'!$A$50:$A$60
Name GP_NM_T: 'Generic Parameters'!$B$50:$M$60
Name GP_OL_Sectors: 'Generic Parameters'!$A$92:$A$102
Name GP_OL_T: 'Generic Parameters'!$B$92:$M$102
Name GP_PE_Sectors: 'Generic Parameters'!$A$190:$A$200
Name GP_PE_T: 'Generic Parameters'!$B$190:$M$200
Name GP_PF_Sectors: 'Generic Parameters'!$A$218:$A$228
Name GP_PF_T: 'Generic Parameters'!$B$218:$M$228
Name GP_PR_Sectors: 'Generic Parameters'!$A$246:$A$256
Name GP_PR_T: 'Generic Parameters'!$B$246:$M$256
Name GP_RG_Sectors: 'Generic Parameters'!$A$64:$A$74
Name GP_RG_T: 'Generic Parameters'!$B$64:$M$74
Name GP_ROE_Sectors: 'Generic Parameters'!$A$22:$A$32
Name GP_ROE_T: 'Generic Parameters'!$B$22:$M$32
Name GP_ROIC_Sectors: 'Generic Parameters'!$A$36:$A$46
Name GP_ROIC_T: 'Generic Parameters'!$B$36:$M$46
Name GP_W_P1: 'Generic Parameters'!$B$6:$B$16
Name GP_W_P2: 'Generic Parameters'!$C$6:$C$16
Name GP_W_P3: 'Generic Parameters'!$D$6:$D$16
Name GP_W_P4: 'Generic Parameters'!$E$6:$E$16
Name GP_W_P5: 'Generic Parameters'!$F$6:$F$16
Name GP_W_P6: 'Generic Parameters'!$G$6:$G$16
Name GP_Weights_Sectors: 'Generic Parameters'!$A$6:$A$16
Name SP_AT_Sectors: #REF!
Name SP_AT_T: #REF!
Name SP_CC_Sectors: #REF!
Name SP_CC_T: #REF!
Name SP_CR_Sectors: #REF!
Name SP_CR_T: #REF!
Name SP_DSO_Sectors: #REF!
Name SP_DSO_T: #REF!
Name SP_FCF_Sectors: #REF!
Name SP_FCF_T: #REF!
Name SP_GM_Sectors: #REF!
Name SP_GM_T: #REF!
Name SP_IC_Sectors: #REF!
Name SP_IC_T: #REF!
Name SP_ND_Sectors: #REF!
Name SP_ND_T: #REF!
Name SP_OL_Sectors: #REF!

Sheet Generic Scoring
A1: GENERIC EQUITY SCORING MODEL | V1: SECTOR-ADJUSTED SCORING ENGINE | AN1: PILLAR SCORES | AT1: FINAL | AU1: -0.018 | AY1: VALUATION
A2: Cols D-U: Manual inputs | Cols V-AM: Auto-scored | Cols AN-AS: Pillar aggregation | Col AT: Final | AZ2: Consenso/Morningstar | BA2: DCF Simplified | BD2: MOMENTUM / TECHNICAL | BG2: MOMENTUM SCORING | BJ2: P7 | BK2: COMBINED SCORE (F40/V20/M25/TQ15)
A3: Company | B3: GICS Sector | C3: ROE (%) | D3: ROIC (%) | E3: Net Margin (%) | F3: Rev Gr 3Y (%) | G3: EPS Gr 3Y (%) | H3: Op Lev (x) | I3: ND/EBITDA | J3: Curr Ratio | K3: Int Cov (x) | L3: FCF Mar (%) | M3: FCF/NI (x) | N3: Capex/Rev (%) | O3: Fwd P/E | P3: EV/EBITDA | Q3: P/FCF | R3: Div Yield (%) | S3: Payout (%) | T3: Buyback (%) | U3: S.ROE | V3: S.ROIC | W3: S.NM | X3: S.RevGr | Y3: S.EPSGr | Z3: S.OpLev | AA3: S.Debt | AB3: S.CR | AC3: S.IC | AD3: S.FCFm | AE3: S.FCFni | AF3: S.Capex | AG3: S.PE | AH3: S.EVEB | AI3: S.PFCF | AJ3: S.DivY | AK3: S.Payout | AL3: S.Buyb | AM3: P1.Adj | AN3: P2.Adj | AO3: P3.Adj | AP3: P4.Adj | AQ3: P5.Val | AR3: P6.Adj | AS3: SA SCORE | AT3: ROIC 5Y Trend | AU3: Margin Stability | AV3: FCF Consistency | AW3: Trend Quality | AX3: Ticker | AY3: Current Price 🔄 | AZ3: Fair Value | BA3: DCF Fair Value | BB3: Upside % | BD3: Price/SMA200 (%) | BE3: RSI 14 | BF3: Mom 6M (%) | BG3: S.SMA | BH3: S.RSI | BI3: S.Mom | BJ3: P7.Mom | BK3: FVM Score | BL3: FVM Band | BM3: SIGNAL
A4: NVIDIA Corp | B4: Information Technology | C4: 0.9 | D4: 0.75 | E4: 0.55 | F4: 0.94 | G4: 1.2 | H4: 2.1 | I4: -1.5 | J4: 4.2 | K4: 50 | L4: 0.31 | M4: 1.15 | N4: 0.04 | O4: 32 | P4: 28 | Q4: 40 | R4: 0.0003 | S4: 0.01 | T4: 0.01 | U4: =IF(OR($B4="",C4=""),"",IF(ISERROR(MATCH($B4,GP_ROE_Sectors,0)),0,IF(C4>=INDEX(GP_ROE_T,MATCH($B4,GP_ROE_Sectors,0),1),INDEX(GP_ROE_T,MATCH($B4,GP_ROE_Sectors,0),2),IF(C4>=INDEX(GP_ROE_T,MATCH($B4,GP_ROE_Sectors,0),3),INDEX(GP_ROE_T,MATCH($B4,GP_ROE_Sectors,0),4),IF(C4>=INDEX(GP_ROE_T,MATCH($B4,GP_ROE_Sectors,0),5),INDEX(GP_ROE_T,MATCH($B4,GP_ROE_Sectors,0),6),IF(C4>=INDEX(GP_ROE_T,MATCH($B4,GP_ROE_Sectors,0),7),INDEX(GP_ROE_T,MATCH($B4,GP_ROE_Sectors,0),8),IF(C4>=INDEX(GP_ROE_T,MATCH($B4,GP_ROE_Sectors,0),9),INDEX(GP_ROE_T,MATCH($B4,GP_ROE_Sectors,0),10),IF(C4>=INDEX(GP_ROE_T,MATCH($B4,GP_ROE_Sectors,0),11),INDEX(GP_ROE_T,MATCH($B4,GP_ROE_Sectors,0),12),0)))))))) -> 100 | V4: =IF(OR($B4="",D4=""),"",IF(ISERROR(MATCH($B4,GP_ROIC_Sectors,0)),0,IF(D4>=INDEX(GP_ROIC_T,MATCH($B4,GP_ROIC_Sectors,0),1),INDEX(GP_ROIC_T,MATCH($B4,GP_ROIC_Sectors,0),2),IF(D4>=INDEX(GP_ROIC_T,MATCH($B4,GP_ROIC_Sectors,0),3),INDEX(GP_ROIC_T,MATCH($B4,GP_ROIC_Sectors,0),4),IF(D4>=INDEX(GP_ROIC_T,MATCH($B4,GP_ROIC_Sectors,0),5),INDEX(GP_ROIC_T,MATCH($B4,GP_ROIC_Sectors,0),6),IF(D4>=INDEX(GP_ROIC_T,MATCH($B4,GP_ROIC_Sectors,0),7),INDEX(GP_ROIC_T,MATCH($B4,GP_ROIC_Sectors,0),8),IF(D4>=INDEX(GP_ROIC_T,MATCH($B4,GP_ROIC_Sectors,0),9),INDEX(GP_ROIC_T,MATCH($B4,GP_ROIC_Sectors,0),10),IF(D4>=INDEX(GP_ROIC_T,MATCH($B4,GP_ROIC_Sectors,0),11),INDEX(GP_ROIC_T,MATCH($B4,GP_ROIC_Sectors,0),12),0)))))))) -> 100 | W4: =IF(OR($B4="",E4=""),"",IF(ISERROR(MATCH($B4,GP_NM_Sectors,0)),0,IF(E4>=INDEX(GP_NM_T,MATCH($B4,GP_NM_Sectors,0),1),INDEX(GP_NM_T,MATCH($B4,GP_NM_Sectors,0),2),IF(E4>=INDEX(GP_NM_T,MATCH($B4,GP_NM_Sectors,0),3),INDEX(GP_NM_T,MATCH($B4,GP_NM_Sectors,0),4),IF(E4>=INDEX(GP_NM_T,MATCH($B4,GP_NM_Sectors,0),5),INDEX(GP_NM_T,MATCH($B4,GP_NM_Sectors,0),6),IF(E4>=INDEX(GP_NM_T,MATCH($B4,GP_NM_Sectors,0),7),INDEX(GP_NM_T,MATCH($B4,GP_NM_Sectors,0),8),IF(E4>=INDEX(GP_NM_T,MATCH($B4,GP_NM_Sectors,0),9),INDEX(GP_NM_T,MATCH($B4,GP_NM_Sectors,0),10),IF(E4>=INDEX(GP_NM_T,MATCH($B4,GP_NM_Sectors,0),11),INDEX(GP_NM_T,MATCH($B4,GP_NM_Sectors,0),12),0)))))))) -> 100 | X4: =IF(OR($B4="",F4=""),"",IF(ISERROR(MATCH($B4,GP_RG_Sectors,0)),0,IF(F4>=INDEX(GP_RG_T,MATCH($B4,GP_RG_Sectors,0),1),INDEX(GP_RG_T,MATCH($B4,GP_RG_Sectors,0),2),IF(F4>=INDEX(GP_RG_T,MATCH($B4,GP_RG_Sectors,0),3),INDEX(GP_RG_T,MATCH($B4,GP_RG_Sectors,0),4),IF(F4>=INDEX(GP_RG_T,MATCH($B4,GP_RG_Sectors,0),5),INDEX(GP_RG_T,MATCH($B4,GP_RG_Sectors,0),6),IF(F4>=INDEX(GP_RG_T,MATCH($B4,GP_RG_Sectors,0),7),INDEX(GP_RG_T,MATCH($B4,GP_RG_Sectors,0),8),IF(F4>=INDEX(GP_RG_T,MATCH($B4,GP_RG_Sectors,0),9),INDEX(GP_RG_T,MATCH($B4,GP_RG_Sectors,0),10),IF(F4>=INDEX(GP_RG_T,MATCH($B4,GP_RG_Sectors,0),11),INDEX(GP_RG_T,MATCH($B4,GP_RG_Sectors,0),12),0)))))))) -> 100 | Y4: =IF(OR($B4="",G4=""),"",IF(ISERROR(MATCH($B4,GP_EG_Sectors,0)),0,IF(G4>=INDEX(GP_EG_T,MATCH($B4,GP_EG_Sectors,0),1),INDEX(GP_EG_T,MATCH($B4,GP_EG_Sectors,0),2),IF(G4>=INDEX(GP_EG_T,MATCH($B4,GP_EG_Sectors,0),3),INDEX(GP_EG_T,MATCH($B4,GP_EG_Sectors,0),4),IF(G4>=INDEX(GP_EG_T,MATCH($B4,GP_EG_Sectors,0),5),INDEX(GP_EG_T,MATCH($B4,GP_EG_Sectors,0),6),IF(G4>=INDEX(GP_EG_T,MATCH($B4,GP_EG_Sectors,0),7),INDEX(GP_EG_T,MATCH($B4,GP_EG_Sectors,0),8),IF(G4>=INDEX(GP_EG_T,MATCH($B4,GP_EG_Sectors,0),9),INDEX(GP_EG_T,MATCH($B4,GP_EG_Sectors,0),10),IF(G4>=INDEX(GP_EG_T,MATCH($B4,GP_EG_Sectors,0),11),INDEX(GP_EG_T,MATCH($B4,GP_EG_Sectors,0),12),0)))))))) -> 100 | Z4: =IF(OR($B4="",H4=""),"",IF(ISERROR(MATCH($B4,GP_OL_Sectors,0)),0,IF(H4>=INDEX(GP_OL_T,MATCH($B4,GP_OL_Sectors,0),1),INDEX(GP_OL_T,MATCH($B4,GP_OL_Sectors,0),2),IF(H4>=INDEX(GP_OL_T,MATCH($B4,GP_OL_Sectors,0),3),INDEX(GP_OL_T,MATCH($B4,GP_OL_Sectors,0),4),IF(H4>=INDEX(GP_OL_T,MATCH($B4,GP_OL_Sectors,0),5),INDEX(GP_OL_T,MATCH($B4,GP_OL_Sectors,0),6),IF(H4>=INDEX(GP_OL_T,MATCH($B4,GP_OL_Sectors,0),7),INDEX(GP_OL_T,MATCH($B4,GP_OL_Sectors,0),8),IF(H4>=INDEX(GP_OL_T,MATCH($B4,GP_OL_Sectors,0),9),INDEX(GP_OL_T,MATCH($B4,GP_OL_Sectors,0),10),IF(H4>=INDEX(GP_OL_T,MATCH($B4,GP_OL_Sectors,0),11),INDEX(GP_OL_T,MATCH($B4,GP_OL_Sectors,0),12),0)))))))) -> 100 | AA4: =IF(OR($B4="",I4=""),"",IF(ISERROR(MATCH($B4,GP_ND_Sectors,0)),0,IF(I4<=INDEX(GP_ND_T,MATCH($B4,GP_ND_Sectors,0),1),INDEX(GP_ND_T,MATCH($B4,GP_ND_Sectors,0),2),IF(I4<=INDEX(GP_ND_T,MATCH($B4,GP_ND_Sectors,0),3),INDEX(GP_ND_T,MATCH($B4,GP_ND_Sectors,0),4),IF(I4<=INDEX(GP_ND_T,MATCH($B4,GP_ND_Sectors,0),5),INDEX(GP_ND_T,MATCH($B4,GP_ND_Sectors,0),6),IF(I4<=INDEX(GP_ND_T,MATCH($B4,GP_ND_Sectors,0),7),INDEX(GP_ND_T,MATCH($B4,GP_ND_Sectors,0),8),IF(I4<=INDEX(GP_ND_T,MATCH($B4,GP_ND_Sectors,0),9),INDEX(GP_ND_T,MATCH($B4,GP_ND_Sectors,0),10),IF(I4<=INDEX(GP_ND_T,MATCH($B4,GP_ND_Sectors,0),11),INDEX(GP_ND_T,MATCH($B4,GP_ND_Sectors,0),12),0)))))))) -> 100 | AB4: =IF(OR($B4="",J4=""),"",IF(ISERROR(MATCH($B4,GP_CR_Sectors,0)),0,IF(J4>=INDEX(GP_CR_T,MATCH($B4,GP_CR_Sectors,0),1),INDEX(GP_CR_T,MATCH($B4,GP_CR_Sectors,0),2),IF(J4>=INDEX(GP_CR_T,MATCH($B4,GP_CR_Sectors,0),3),INDEX(GP_CR_T,MATCH($B4,GP_CR_Sectors,0),4),IF(J4>=INDEX(GP_CR_T,MATCH($B4,GP_CR_Sectors,0),5),INDEX(GP_CR_T,MATCH($B4,GP_CR_Sectors,0),6),IF(J4>=INDEX(GP_CR_T,MATCH($B4,GP_CR_Sectors,0),7),INDEX(GP_CR_T,MATCH($B4,GP_CR_Sectors,0),8),IF(J4>=INDEX(GP_CR_T,MATCH($B4,GP_CR_Sectors,0),9),INDEX(GP_CR_T,MATCH($B4,GP_CR_Sectors,0),10),IF(J4>=INDEX(GP_CR_T,MATCH($B4,GP_CR_Sectors,0),11),INDEX(GP_CR_T,MATCH($B4,GP_CR_Sectors,0),12),0)))))))) -> 100 | AC4: =IF(OR($B4="",K4=""),"",IF(ISERROR(MATCH($B4,GP_IC_Sectors,0)),0,IF(K4>=INDEX(GP_IC_T,MATCH($B4,GP_IC_Sectors,0),1),INDEX(GP_IC_T,MATCH($B4,GP_IC_Sectors,0),2),IF(K4>=INDEX(GP_IC_T,MATCH($B4,GP_IC_Sectors,0),3),INDEX(GP_IC_T,MATCH($B4,GP_IC_Sectors,0),4),IF(K4>=INDEX(GP_IC_T,MATCH($B4,GP_IC_Sectors,0),5),INDEX(GP_IC_T,MATCH($B4,GP_IC_Sectors,0),6),IF(K4>=INDEX(GP_IC_T,MATCH($B4,GP_IC_Sectors,0),7),INDEX(GP_IC_T,MATCH($B4,GP_IC_Sectors,0),8),IF(K4>=INDEX(GP_IC_T,MATCH($B4,GP_IC_Sectors,0),9),INDEX(GP_IC_T,MATCH($B4,GP_IC_Sectors,0),10),IF(K4>=INDEX(GP_IC_T,MATCH($B4,GP_IC_Sectors,0),11),INDEX(GP_IC_T,MATCH($B4,GP_IC_Sectors,0),12),0)))))))) -> 100 | AD4: =IF(OR($B4="",L4=""),"",IF(ISERROR(MATCH($B4,GP_FM_Sectors,0)),0,IF(L4>=INDEX(GP_FM_T,MATCH($B4,GP_FM_Sectors,0),1),INDEX(GP_FM_T,MATCH($B4,GP_FM_Sectors,0),2),IF(L4>=INDEX(GP_FM_T,MATCH($B4,GP_FM_Sectors,0),3),INDEX(GP_FM_T,MATCH($B4,GP_FM_Sectors,0),4),IF(L4>=INDEX(GP_FM_T,MATCH($B4,GP_FM_Sectors,0),5),INDEX(GP_FM_T,MATCH($B4,GP_FM_Sectors,0),6),IF(L4>=INDEX(GP_FM_T,MATCH($B4,GP_FM_Sectors,0),7),INDEX(GP_FM_T,MATCH($B4,GP_FM_Sectors,0),8),IF(L4>=INDEX(GP_FM_T,MATCH($B4,GP_FM_Sectors,0),9),INDEX(GP_FM_T,MATCH($B4,GP_FM_Sectors,0),10),IF(L4>=INDEX(GP_FM_T,MATCH($B4,GP_FM_Sectors,0),11),INDEX(GP_FM_T,MATCH($B4,GP_FM_Sectors,0),12),0)))))))) -> 100 | AE4: =IF(OR($B4="",M4=""),"",IF(ISERROR(MATCH($B4,GP_FN_Sectors,0)),0,IF(M4>=INDEX(GP_FN_T,MATCH($B4,GP_FN_Sectors,0),1),INDEX(GP_FN_T,MATCH($B4,GP_FN_Sectors,0),2),IF(M4>=INDEX(GP_FN_T,MATCH($B4,GP_FN_Sectors,0),3),INDEX(GP_FN_T,MATCH($B4,GP_FN_Sectors,0),4),IF(M4>=INDEX(GP_FN_T,MATCH($B4,GP_FN_Sectors,0),5),INDEX(GP_FN_T,MATCH($B4,GP_FN_Sectors,0),6),IF(M4>=INDEX(GP_FN_T,MATCH($B4,GP_FN_Sectors,0),7),INDEX(GP_FN_T,MATCH($B4,GP_FN_Sectors,0),8),IF(M4>=INDEX(GP_FN_T,MATCH($B4,GP_FN_Sectors,0),9),INDEX(GP_FN_T,MATCH($B4,GP_FN_Sectors,0),10),IF(M4>=INDEX(GP_FN_T,MATCH($B4,GP_FN_Sectors,0),11),INDEX(GP_FN_T,MATCH($B4,GP_FN_Sectors,0),12),0)))))))) -> 88 | AF4: =IF(OR($B4="",N4=""),"",IF(ISERROR(MATCH($B4,GP_CX_Sectors,0)),0,IF(N4<=INDEX(GP_CX_T,MATCH($B4,GP_CX_Sectors,0),1),INDEX(GP_CX_T,MATCH($B4,GP_CX_Sectors,0),2),IF(N4<=INDEX(GP_CX_T,MATCH($B4,GP_CX_Sectors,0),3),INDEX(GP_CX_T,MATCH($B4,GP_CX_Sectors,0),4),IF(N4<=INDEX(GP_CX_T,MATCH($B4,GP_CX_Sectors,0),5),INDEX(GP_CX_T,MATCH($B4,GP_CX_Sectors,0),6),IF(N4<=INDEX(GP_CX_T,MATCH($B4,GP_CX_Sectors,0),7),INDEX(GP_CX_T,MATCH($B4,GP_CX_Sectors,0),8),IF(N4<=INDEX(GP_CX_T,MATCH($B4,GP_CX_Sectors,0),9),INDEX(GP_CX_T,MATCH($B4,GP_CX_Sectors,0),10),IF(N4<=INDEX(GP_CX_T,MATCH($B4,GP_CX_Sectors,0),11),INDEX(GP_CX_T,MATCH($B4,GP_CX_Sectors,0),12),0)))))))) -> 85 | AG4: =IF(OR($B4="",O4=""),"",IF(ISERROR(MATCH($B4,GP_PE_Sectors,0)),0,IF(O4<=INDEX(GP_PE_T,MATCH($B4,GP_PE_Sectors,0),1),INDEX(GP_PE_T,MATCH($B4,GP_PE_Sectors,0),2),IF(O4<=INDEX(GP_PE_T,MATCH($B4,GP_PE_Sectors,0),3),INDEX(GP_PE_T,MATCH($B4,GP_PE_Sectors,0),4),IF(O4<=INDEX(GP_PE_T,MATCH($B4,GP_PE_Sectors,0),5),INDEX(GP_PE_T,MATCH($B4,GP_PE_Sectors,0),6),IF(O4<=INDEX(GP_PE_T,MATCH($B4,GP_PE_Sectors,0),7),INDEX(GP_PE_T,MATCH($B4,GP_PE_Sectors,0),8),IF(O4<=INDEX(GP_PE_T,MATCH($B4,GP_PE_Sectors,0),9),INDEX(GP_PE_T,MATCH($B4,GP_PE_Sectors,0),10),IF(O4<=INDEX(GP_PE_T,MATCH($B4,GP_PE_Sectors,0),11),INDEX(GP_PE_T,MATCH($B4,GP_PE_Sectors,0),12),0)))))))) -> 48 | AH4: =IF(OR($B4="",P4=""),"",IF(ISERROR(MATCH($B4,GP_EV_Sectors,0)),0,IF(P4<=INDEX(GP_EV_T,MATCH($B4,GP_EV_Sectors,0),1),INDEX(GP_EV_T,MATCH($B4,GP_EV_Sectors,0),2),IF(P4<=INDEX(GP_EV_T,MATCH($B4,GP_EV_Sectors,0),3),INDEX(GP_EV_T,MATCH($B4,GP_EV_Sectors,0),4),IF(P4<=INDEX(GP_EV_T,MATCH($B4,GP_EV_Sectors,0),5),INDEX(GP_EV_T,MATCH($B4,GP_EV_Sectors,0),6),IF(P4<=INDEX(GP_EV_T,MATCH($B4,GP_EV_Sectors,0),7),INDEX(GP_EV_T,MATCH($B4,GP_EV_Sectors,0),8),IF(P4<=INDEX(GP_EV_T,MATCH($B4,GP_EV_Sectors,0),9),INDEX(GP_EV_T,MATCH($B4,GP_EV_Sectors,0),10),IF(P4<=INDEX(GP_EV_T,MATCH($B4,GP_EV_Sectors,0),11),INDEX(GP_EV_T,MATCH($B4,GP_EV_Sectors,0),12),0)))))))) -> 48 | AI4: =IF(OR($B4="",Q4=""),"",IF(ISERROR(MATCH($B4,GP_PF_Sectors,0)),0,IF(Q4<=INDEX(GP_PF_T,MATCH($B4,GP_PF_Sectors,0),1),INDEX(GP_PF_T,MATCH($B4,GP_PF_Sectors,0),2),IF(Q4<=INDEX(GP_PF_T,MATCH($B4,GP_PF_Sectors,0),3),INDEX(GP_PF_T,MATCH($B4,GP_PF_Sectors,0),4),IF(Q4<=INDEX(GP_PF_T,MATCH($B4,GP_PF_Sectors,0),5),INDEX(GP_PF_T,MATCH($B4,GP_PF_Sectors,0),6),IF(Q4<=INDEX(GP_PF_T,MATCH($B4,GP_PF_Sectors,0),7),INDEX(GP_PF_T,MATCH($B4,GP_PF_Sectors,0),8),IF(Q4<=INDEX(GP_PF_T,MATCH($B4,GP_PF_Sectors,0),9),INDEX(GP_PF_T,MATCH($B4,GP_PF_Sectors,0),10),IF(Q4<=INDEX(GP_PF_T,MATCH($B4,GP_PF_Sectors,0),11),INDEX(GP_PF_T,MATCH($B4,GP_PF_Sectors,0),12),0)))))))) -> 48 | AJ4: =IF(OR($B4="",R4=""),"",IF(ISERROR(MATCH($B4,GP_DY_Sectors,0)),0,IF(R4>=INDEX(GP_DY_T,MATCH($B4,GP_DY_Sectors,0),1),INDEX(GP_DY_T,MATCH($B4,GP_DY_Sectors,0),2),IF(R4>=INDEX(GP_DY_T,MATCH($B4,GP_DY_Sectors,0),3),INDEX(GP_DY_T,MATCH($B4,GP_DY_Sectors,0),4),IF(R4>=INDEX(GP_DY_T,MATCH($B4,GP_DY_Sectors,0),5),INDEX(GP_DY_T,MATCH($B4,GP_DY_Sectors,0),6),IF(R4>=INDEX(GP_DY_T,MATCH($B4,GP_DY_Sectors,0),7),INDEX(GP_DY_T,MATCH($B4,GP_DY_Sectors,0),8),IF(R4>=INDEX(GP_DY_T,MATCH($B4,GP_DY_Sectors,0),9),INDEX(GP_DY_T,MATCH($B4,GP_DY_Sectors,0),10),IF(R4>=INDEX(GP_DY_T,MATCH($B4,GP_DY_Sectors,0),11),INDEX(GP_DY_T,MATCH($B4,GP_DY_Sectors,0),12),0)))))))) -> 5 | AK4: =IF(OR($B4="",S4=""),"",IF(ISERROR(MATCH($B4,GP_PR_Sectors,0)),0,IF(S4>=INDEX(GP_PR_T,MATCH($B4,GP_PR_Sectors,0),1),INDEX(GP_PR_T,MATCH($B4,GP_PR_Sectors,0),2),IF(S4>=INDEX(GP_PR_T,MATCH($B4,GP_PR_Sectors,0),3),INDEX(GP_PR_T,MATCH($B4,GP_PR_Sectors,0),4),IF(S4>=INDEX(GP_PR_T,MATCH($B4,GP_PR_Sectors,0),5),INDEX(GP_PR_T,MATCH($B4,GP_PR_Sectors,0),6),IF(S4>=INDEX(GP_PR_T,MATCH($B4,GP_PR_Sectors,0),7),INDEX(GP_PR_T,MATCH($B4,GP_PR_Sectors,0),8),IF(S4>=INDEX(GP_PR_T,MATCH($B4,GP_PR_Sectors,0),9),INDEX(GP_PR_T,MATCH($B4,GP_PR_Sectors,0),10),IF(S4>=INDEX(GP_PR_T,MATCH($B4,GP_PR_Sectors,0),11),INDEX(GP_PR_T,MATCH($B4,GP_PR_Sectors,0),12),0)))))))) -> 0 | AL4: =IF(OR($B4="",T4=""),"",IF(ISERROR(MATCH($B4,GP_BY_Sectors,0)),0,IF(T4>=INDEX(GP_BY_T,MATCH($B4,GP_BY_Sectors,0),1),INDEX(GP_BY_T,MATCH($B4,GP_BY_Sectors,0),2),IF(T4>=INDEX(GP_BY_T,MATCH($B4,GP_BY_Sectors,0),3),INDEX(GP_BY_T,MATCH($B4,GP_BY_Sectors,0),4),IF(T4>=INDEX(GP_BY_T,MATCH($B4,GP_BY_Sectors,0),5),INDEX(GP_BY_T,MATCH($B4,GP_BY_Sectors,0),6),IF(T4>=INDEX(GP_BY_T,MATCH($B4,GP_BY_Sectors,0),7),INDEX(GP_BY_T,MATCH($B4,GP_BY_Sectors,0),8),IF(T4>=INDEX(GP_BY_T,MATCH($B4,GP_BY_Sectors,0),9),INDEX(GP_BY_T,MATCH($B4,GP_BY_Sectors,0),10),IF(T4>=INDEX(GP_BY_T,MATCH($B4,GP_BY_Sectors,0),11),INDEX(GP_BY_T,MATCH($B4,GP_BY_Sectors,0),12),0)))))))) -> 50 | AM4: =IF($B4="","",U4*0.35+V4*0.35+W4*0.3) -> 100 | AN4: =IF($B4="","",X4*0.4+Y4*0.35+Z4*0.25) -> 100 | AO4: =IF($B4="","",AA4*0.35+AB4*0.3+AC4*0.35) -> 100 | AP4: =IF($B4="","",AD4*0.4+AE4*0.35+AF4*0.25) -> 92.05 | AQ4: =IF($B4="","",AG4*0.35+AH4*0.35+AI4*0.3) -> 48 | AR4: =IF($B4="","",AJ4*0.45+AK4*0.2+AL4*0.35) -> 19.75 | AS4: =IF($B4="","",MIN(100,MAX(0,ROUND(AM4*INDEX(GP_W_P1,MATCH($B4,GP_Weights_Sectors,0))+AN4*INDEX(GP_W_P2,MATCH($B4,GP_Weights_Sectors,0))+AO4*INDEX(GP_W_P3,MATCH($B4,GP_Weights_Sectors,0))+AP4*INDEX(GP_W_P4,MATCH($B4,GP_Weights_Sectors,0))+AQ4*INDEX(GP_W_P5,MATCH($B4,GP_Weights_Sectors,0))+AR4*INDEX(GP_W_P6,MATCH($B4,GP_Weights_Sectors,0)),0)))) -> 83 | AT4: 3 | AU4: 3 | AV4: 4 | AW4: =MAX(-10,MIN(10,AT4+AU4+AV4)) -> 10 | AX4: #VALUE! | AY4: {=_FV(AX4,"PRECIO")} -> 171.24 | AZ4: 240 | BA4: =IFERROR(INDEX('DCF Simplified'!$Y$4:$Y$38,MATCH(A4,'DCF Simplified'!$A$4:$A$38,0)),"") -> 69.398445 | BB4: =IF(OR(AY4="",AZ4=""),"",(AZ4-AY4)/AY4) -> 0.4015417 | BD4: 0.12 | BE4: 62 | BF4: 0.35 | BG4: =IF(BD4>0.1,100,IF(BD4>0.05,80,IF(BD4>0,65,IF(BD4>-0.05,45,IF(BD4>-0.1,25,10))))) -> 100 | BH4: =IF(AND(BE4>=40,BE4<=60),70,IF(AND(BE4>60,BE4<=70),85,IF(BE4>70,50,IF(AND(BE4>=30,BE4<40),55,40)))) -> 85 | BI4: =IF(BF4>0.2,100,IF(BF4>0.1,80,IF(BF4>0,65,IF(BF4>-0.1,45,IF(BF4>-0.2,25,10))))) -> 100 | BJ4: =ROUND(BG4*0.4+BH4*0.25+BI4*0.35,1) -> 96.3 | BK4: =IF(OR(AS4="",AQ4="",BJ4=""),"",ROUND(AS4*0.4+MAX(15,MIN(90,AQ4))*0.2+BJ4*0.25+MIN(100,MAX(0,AW4*10))*0.15,0)) -> 82 | BL4: =IF(BK4="","",IF(BK4>=85,"🟢 STRONG",IF(BK4>=70,"🟡 FAVORABLE",IF(BK4>=55,"⚪ NEUTRAL",IF(BK4>=40,"🟠 WEAK","🔴 AVOID"))))) -> 🟡 FAVORABLE | BM4: =IF(BK4="","",IF(AND(BK4>=75,BJ4>=70,AW4>=6),"🚀 STRONG BUY",IF(AND(BK4>=65,BJ4>=55),"✅ BUY",IF(BK4>=55,"⚠️ HOLD",IF(OR(BK4<45,AND(BJ4<35,AW4<3)),"🔴 SELL","🟠 UNDERWEIGHT"))))) -> 🚀 STRONG BUY
A5: Johnson & Johnson | B5: Health Care | C5: 0.22 | D5: 0.18 | E5: 0.18 | F5: 0.04 | G5: 0.03 | H5: 0.9 | I5: 1.2 | J5: 1.3 | K5: 8 | L5: 0.16 | M5: 0.95 | N5: 0.05 | O5: 16 | P5: 12 | Q5: 20 | R5: 0.032 | S5: 0.48 | T5: 0.02 | U5: =IF(OR($B5="",C5=""),"",IF(ISERROR(MATCH($B5,GP_ROE_Sectors,0)),0,IF(C5>=INDEX(GP_ROE_T,MATCH($B5,GP_ROE_Sectors,0),1),INDEX(GP_ROE_T,MATCH($B5,GP_ROE_Sectors,0),2),IF(C5>=INDEX(GP_ROE_T,MATCH($B5,GP_ROE_Sectors,0),3),INDEX(GP_ROE_T,MATCH($B5,GP_ROE_Sectors,0),4),IF(C5>=INDEX(GP_ROE_T,MATCH($B5,GP_ROE_Sectors,0),5),INDEX(GP_ROE_T,MATCH($B5,GP_ROE_Sectors,0),6),IF(C5>=INDEX(GP_ROE_T,MATCH($B5,GP_ROE_Sectors,0),7),INDEX(GP_ROE_T,MATCH($B5,GP_ROE_Sectors,0),8),IF(C5>=INDEX(GP_ROE_T,MATCH($B5,GP_ROE_Sectors,0),9),INDEX(GP_ROE_T,MATCH($B5,GP_ROE_Sectors,0),10),IF(C5>=INDEX(GP_ROE_T,MATCH($B5,GP_ROE_Sectors,0),11),INDEX(GP_ROE_T,MATCH($B5,GP_ROE_Sectors,0),12),0)))))))) -> 88 | V5: =IF(OR($B5="",D5=""),"",IF(ISERROR(MATCH($B5,GP_ROIC_Sectors,0)),0,IF(D5>=INDEX(GP_ROIC_T,MATCH($B5,GP_ROIC_Sectors,0),1),INDEX(GP_ROIC_T,MATCH($B5,GP_ROIC_Sectors,0),2),IF(D5>=INDEX(GP_ROIC_T,MATCH($B5,GP_ROIC_Sectors,0),3),INDEX(GP_ROIC_T,MATCH($B5,GP_ROIC_Sectors,0),4),IF(D5>=INDEX(GP_ROIC_T,MATCH($B5,GP_ROIC_Sectors,0),5),INDEX(GP_ROIC_T,MATCH($B5,GP_ROIC_Sectors,0),6),IF(D5>=INDEX(GP_ROIC_T,MATCH($B5,GP_ROIC_Sectors,0),7),INDEX(GP_ROIC_T,MATCH($B5,GP_ROIC_Sectors,0),8),IF(D5>=INDEX(GP_ROIC_T,MATCH($B5,GP_ROIC_Sectors,0),9),INDEX(GP_ROIC_T,MATCH($B5,GP_ROIC_Sectors,0),10),IF(D5>=INDEX(GP_ROIC_T,MATCH($B5,GP_ROIC_Sectors,0),11),INDEX(GP_ROIC_T,MATCH($B5,GP_ROIC_Sectors,0),12),0)))))))) -> 88 | W5: =IF(OR($B5="",E5=""),"",IF(ISERROR(MATCH($B5,GP_NM_Sectors,0)),0,IF(E5>=INDEX(GP_NM_T,MATCH($B5,GP_NM_Sectors,0),1),INDEX(GP_NM_T,MATCH($B5,GP_NM_Sectors,0),2),IF(E5>=INDEX(GP_NM_T,MATCH($B5,GP_NM_Sectors,0),3),INDEX(GP_NM_T,MATCH($B5,GP_NM_Sectors,0),4),IF(E5>=INDEX(GP_NM_T,MATCH($B5,GP_NM_Sectors,0),5),INDEX(GP_NM_T,MATCH($B5,GP_NM_Sectors,0),6),IF(E5>=INDEX(GP_NM_T,MATCH($B5,GP_NM_Sectors,0),7),INDEX(GP_NM_T,MATCH($B5,GP_NM_Sectors,0),8),IF(E5>=INDEX(GP_NM_T,MATCH($B5,GP_NM_Sectors,0),9),INDEX(GP_NM_T,MATCH($B5,GP_NM_Sectors,0),10),IF(E5>=INDEX(GP_NM_T,MATCH($B5,GP_NM_Sectors,0),11),INDEX(GP_NM_T,MATCH($B5,GP_NM_Sectors,0),12),0)))))))) -> 88 | X5: =IF(OR($B5="",F5=""),"",IF(ISERROR(MATCH($B5,GP_RG_Sectors,0)),0,IF(F5>=INDEX(GP_RG_T,MATCH($B5,GP_RG_Sectors,0),1),INDEX(GP_RG_T,MATCH($B5,GP_RG_Sectors,0),2),IF(F5>=INDEX(GP_RG_T,MATCH($B5,GP_RG_Sectors,0),3),INDEX(GP_RG_T,MATCH($B5,GP_RG_Sectors,0),4),IF(F5>=INDEX(GP_RG_T,MATCH($B5,GP_RG_Sectors,0),5),INDEX(GP_RG_T,MATCH($B5,GP_RG_Sectors,0),6),IF(F5>=INDEX(GP_RG_T,MATCH($B5,GP_RG_Sectors,0),7),INDEX(GP_RG_T,MATCH($B5,GP_RG_Sectors,0),8),IF(F5>=INDEX(GP_RG_T,MATCH($B5,GP_RG_Sectors,0),9),INDEX(GP_RG_T,MATCH($B5,GP_RG_Sectors,0),10),IF(F5>=INDEX(GP_RG_T,MATCH($B5,GP_RG_Sectors,0),11),INDEX(GP_RG_T,MATCH($B5,GP_RG_Sectors,0),12),0)))))))) -> 35 | Y5: =IF(OR($B5="",G5=""),"",IF(ISERROR(MATCH($B5,GP_EG_Sectors,0)),0,IF(G5>=INDEX(GP_EG_T,MATCH($B5,GP_EG_Sectors,0),1),INDEX(GP_EG_T,MATCH($B5,GP_EG_Sectors,0),2),IF(G5>=INDEX(GP_EG_T,MATCH($B5,GP_EG_Sectors,0),3),INDEX(GP_EG_T,MATCH($B5,GP_EG_Sectors,0),4),IF(G5>=INDEX(GP_EG_T,MATCH($B5,GP_EG_Sectors,0),5),INDEX(GP_EG_T,MATCH($B5,GP_EG_Sectors,0),6),IF(G5>=INDEX(GP_EG_T,MATCH($B5,GP_EG_Sectors,0),7),INDEX(GP_EG_T,MATCH($B5,GP_EG_Sectors,0),8),IF(G5>=INDEX(GP_EG_T,MATCH($B5,GP_EG_Sectors,0),9),INDEX(GP_EG_T,MATCH($B5,GP_EG_Sectors,0),10),IF(G5>=INDEX(GP_EG_T,MATCH($B5,GP_EG_Sectors,0),11),INDEX(GP_EG_T,MATCH($B5,GP_EG_Sectors,0),12),0)))))))) -> 35 | Z5: =IF(OR($B5="",H5=""),"",IF(ISERROR(MATCH($B5,GP_OL_Sectors,0)),0,IF(H5>=INDEX(GP_OL_T,MATCH($B5,GP_OL_Sectors,0),1),INDEX(GP_OL_T,MATCH($B5,GP_OL_Sectors,0),2),IF(H5>=INDEX(GP_OL_T,MATCH($B5,GP_OL_Sectors,0),3),INDEX(GP_OL_T,MATCH($B5,GP_OL_Sectors,0),4),IF(H5>=INDEX(GP_OL_T,MATCH($B5,GP_OL_Sectors,0),5),INDEX(GP_OL_T,MATCH($B5,GP_OL_Sectors,0),6),IF(H5>=INDEX(GP_OL_T,MATCH($B5,GP_OL_Sectors,0),7),INDEX(GP_OL_T,MATCH($B5,GP_OL_Sectors,0),8),IF(H5>=INDEX(GP_OL_T,MATCH($B5,GP_OL_Sectors,0),9),INDEX(GP_OL_T,MATCH($B5,GP_OL_Sectors,0),10),IF(H5>=INDEX(GP_OL_T,MATCH($B5,GP_OL_Sectors,0),11),INDEX(GP_OL_T,MATCH($B5,GP_OL_Sectors,0),12),0)))))))) -> 52 | AA5: =IF(OR($B5="",I5=""),"",IF(ISERROR(MATCH($B5,GP_ND_Sectors,0)),0,IF(I5<=INDEX(GP_ND_T,MATCH($B5,GP_ND_Sectors,0),1),INDEX(GP_ND_T,MATCH($B5,GP_ND_Sectors,0),2),IF(I5<=INDEX(GP_ND_T,MATCH($B5,GP_ND_Sectors,0),3),INDEX(GP_ND_T,MATCH($B5,GP_ND_Sectors,0),4),IF(I5<=INDEX(GP_ND_T,MATCH($B5,GP_ND_Sectors,0),5),INDEX(GP_ND_T,MATCH($B5,GP_ND_Sectors,0),6),IF(I5<=INDEX(GP_ND_T,MATCH($B5,GP_ND_Sectors,0),7),INDEX(GP_ND_T,MATCH($B5,GP_ND_Sectors,0),8),IF(I5<=INDEX(GP_ND_T,MATCH($B5,GP_ND_Sectors,0),9),INDEX(GP_ND_T,MATCH($B5,GP_ND_Sectors,0),10),IF(I5<=INDEX(GP_ND_T,MATCH($B5,GP_ND_Sectors,0),11),INDEX(GP_ND_T,MATCH($B5,GP_ND_Sectors,0),12),0)))))))) -> 70 | AB5: =IF(OR($B5="",J5=""),"",IF(ISERROR(MATCH($B5,GP_CR_Sectors,0)),0,IF(J5>=INDEX(GP_CR_T,MATCH($B5,GP_CR_Sectors,0),1),INDEX(GP_CR_T,MATCH($B5,GP_CR_Sectors,0),2),IF(J5>=INDEX(GP_CR_T,MATCH($B5,GP_CR_Sectors,0),3),INDEX(GP_CR_T,MATCH($B5,GP_CR_Sectors,0),4),IF(J5>=INDEX(GP_CR_T,MATCH($B5,GP_CR_Sectors,0),5),INDEX(GP_CR_T,MATCH($B5,GP_CR_Sectors,0),6),IF(J5>=INDEX(GP_CR_T,MATCH($B5,GP_CR_Sectors,0),7),INDEX(GP_CR_T,MATCH($B5,GP_CR_Sectors,0),8),IF(J5>=INDEX(GP_CR_T,MATCH($B5,GP_CR_Sectors,0),9),INDEX(GP_CR_T,MATCH($B5,GP_CR_Sectors,0),10),IF(J5>=INDEX(GP_CR_T,MATCH($B5,GP_CR_Sectors,0),11),INDEX(GP_CR_T,MATCH($B5,GP_CR_Sectors,0),12),0)))))))) -> 52 | AC5: =IF(OR($B5="",K5=""),"",IF(ISERROR(MATCH($B5,GP_IC_Sectors,0)),0,IF(K5>=INDEX(GP_IC_T,MATCH($B5,GP_IC_Sectors,0),1),INDEX(GP_IC_T,MATCH($B5,GP_IC_Sectors,0),2),IF(K5>=INDEX(GP_IC_T,MATCH($B5,GP_IC_Sectors,0),3),INDEX(GP_IC_T,MATCH($B5,GP_IC_Sectors,0),4),IF(K5>=INDEX(GP_IC_T,MATCH($B5,GP_IC_Sectors,0),5),INDEX(GP_IC_T,MATCH($B5,GP_IC_Sectors,0),6),IF(K5>=INDEX(GP_IC_T,MATCH($B5,GP_IC_Sectors,0),7),INDEX(GP_IC_T,MATCH($B5,GP_IC_Sectors,0),8),IF(K5>=INDEX(GP_IC_T,MATCH($B5,GP_IC_Sectors,0),9),INDEX(GP_IC_T,MATCH($B5,GP_IC_Sectors,0),10),IF(K5>=INDEX(GP_IC_T,MATCH($B5,GP_IC_Sectors,0),11),INDEX(GP_IC_T,MATCH($B5,GP_IC_Sectors,0),12),0)))))))) -> 85 | AD5: =IF(OR($B5="",L5=""),"",IF(ISERROR(MATCH($B5,GP_FM_Sectors,0)),0,IF(L5>=INDEX(GP_FM_T,MATCH($B5,GP_FM_Sectors,0),1),INDEX(GP_FM_T,MATCH($B5,GP_FM_Sectors,0),2),IF(L5>=INDEX(GP_FM_T,MATCH($B5,GP_FM_Sectors,0),3),INDEX(GP_FM_T,MATCH($B5,GP_FM_Sectors,0),4),IF(L5>=INDEX(GP_FM_T,MATCH($B5,GP_FM_Sectors,0),5),INDEX(GP_FM_T,MATCH($B5,GP_FM_Sectors,0),6),IF(L5>=INDEX(GP_FM_T,MATCH($B5,GP_FM_Sectors,0),7),INDEX(GP_FM_T,MATCH($B5,GP_FM_Sectors,0),8),IF(L5>=INDEX(GP_FM_T,MATCH($B5,GP_FM_Sectors,0),9),INDEX(GP_FM_T,MATCH($B5,GP_FM_Sectors,0),10),IF(L5>=INDEX(GP_FM_T,MATCH($B5,GP_FM_Sectors,0),11),INDEX(GP_FM_T,MATCH($B5,GP_FM_Sectors,0),12),0)))))))) -> 85 | AE5: =IF(OR($B5="",M5=""),"",IF(ISERROR(MATCH($B5,GP_FN_Sectors,0)),0,IF(M5>=INDEX(GP_FN_T,MATCH($B5,GP_FN_Sectors,0),1),INDEX(GP_FN_T,MATCH($B5,GP_FN_Sectors,0),2),IF(M5>=INDEX(GP_FN_T,MATCH($B5,GP_FN_Sectors,0),3),INDEX(GP_FN_T,MATCH($B5,GP_FN_Sectors,0),4),IF(M5>=INDEX(GP_FN_T,MATCH($B5,GP_FN_Sectors,0),5),INDEX(GP_FN_T,MATCH($B5,GP_FN_Sectors,0),6),IF(M5>=INDEX(GP_FN_T,MATCH($B5,GP_FN_Sectors,0),7),INDEX(GP_FN_T,MATCH($B5,GP_FN_Sectors,0),8),IF(M5>=INDEX(GP_FN_T,MATCH($B5,GP_FN_Sectors,0),9),INDEX(GP_FN_T,MATCH($B5,GP_FN_Sectors,0),10),IF(M5>=INDEX(GP_FN_T,MATCH($B5,GP_FN_Sectors,0),11),INDEX(GP_FN_T,MATCH($B5,GP_FN_Sectors,0),12),0)))))))) -> 70 | AF5: =IF(OR($B5="",N5=""),"",IF(ISERROR(MATCH($B5,GP_CX_Sectors,0)),0,IF(N5<=INDEX(GP_CX_T,MATCH($B5,GP_CX_Sectors,0),1),INDEX(GP_CX_T,MATCH($B5,GP_CX_Sectors,0),2),IF(N5<=INDEX(GP_CX_T,MATCH($B5,GP_CX_Sectors,0),3),INDEX(GP_CX_T,MATCH($B5,GP_CX_Sectors,0),4),IF(N5<=INDEX(GP_CX_T,MATCH($B5,GP_CX_Sectors,0),5),INDEX(GP_CX_T,MATCH($B5,GP_CX_Sectors,0),6),IF(N5<=INDEX(GP_CX_T,MATCH($B5,GP_CX_Sectors,0),7),INDEX(GP_CX_T,MATCH($B5,GP_CX_Sectors,0),8),IF(N5<=INDEX(GP_CX_T,MATCH($B5,GP_CX_Sectors,0),9),INDEX(GP_CX_T,MATCH($B5,GP_CX_Sectors,0),10),IF(N5<=INDEX(GP_CX_T,MATCH($B5,GP_CX_Sectors,0),11),INDEX(GP_CX_T,MATCH($B5,GP_CX_Sectors,0),12),0)))))))) -> 85 | AG5: =IF(OR($B5="",O5=""),"",IF(ISERROR(MATCH($B5,GP_PE_Sectors,0)),0,IF(O5<=INDEX(GP_PE_T,MATCH($B5,GP_PE_Sectors,0),1),INDEX(GP_PE_T,MATCH($B5,GP_PE_Sectors,0),2),IF(O5<=INDEX(GP_PE_T,MATCH($B5,GP_PE_Sectors,0),3),INDEX(GP_PE_T,MATCH($B5,GP_PE_Sectors,0),4),IF(O5<=INDEX(GP_PE_T,MATCH($B5,GP_PE_Sectors,0),5),INDEX(GP_PE_T,MATCH($B5,GP_PE_Sectors,0),6),IF(O5<=INDEX(GP_PE_T,MATCH($B5,GP_PE_Sectors,0),7),INDEX(GP_PE_T,MATCH($B5,GP_PE_Sectors,0),8),IF(O5<=INDEX(GP_PE_T,MATCH($B5,GP_PE_Sectors,0),9),INDEX(GP_PE_T,MATCH($B5,GP_PE_Sectors,0),10),IF(O5<=INDEX(GP_PE_T,MATCH($B5,GP_PE_Sectors,0),11),INDEX(GP_PE_T,MATCH($B5,GP_PE_Sectors,0),12),0)))))))) -> 82 | AH5: =IF(OR($B5="",P5=""),"",IF(ISERROR(MATCH($B5,GP_EV_Sectors,0)),0,IF(P5<=INDEX(GP_EV_T,MATCH($B5,GP_EV_Sectors,0),1),INDEX(GP_EV_T,MATCH($B5,GP_EV_Sectors,0),2),IF(P5<=INDEX(GP_EV_T,MATCH($B5,GP_EV_Sectors,0),3),INDEX(GP_EV_T,MATCH($B5,GP_EV_Sectors,0),4),IF(P5<=INDEX(GP_EV_T,MATCH($B5,GP_EV_Sectors,0),5),INDEX(GP_EV_T,MATCH($B5,GP_EV_Sectors,0),6),IF(P5<=INDEX(GP_EV_T,MATCH($B5,GP_EV_Sectors,0),7),INDEX(GP_EV_T,MATCH($B5,GP_EV_Sectors,0),8),IF(P5<=INDEX(GP_EV_T,MATCH($B5,GP_EV_Sectors,0),9),INDEX(GP_EV_T,MATCH($B5,GP_EV_Sectors,0),10),IF(P5<=INDEX(GP_EV_T,MATCH($B5,GP_EV_Sectors,0),11),INDEX(GP_EV_T,MATCH($B5,GP_EV_Sectors,0),12),0)))))))) -> 82 | AI5: =IF(OR($B5="",Q5=""),"",IF(ISERROR(MATCH($B5,GP_PF_Sectors,0)),0,IF(Q5<=INDEX(GP_PF_T,MATCH($B5,GP_PF_Sectors,0),1),INDEX(GP_PF_T,MATCH($B5,GP_PF_Sectors,0),2),IF(Q5<=INDEX(GP_PF_T,MATCH($B5,GP_PF_Sectors,0),3),INDEX(GP_PF_T,MATCH($B5,GP_PF_Sectors,0),4),IF(Q5<=INDEX(GP_PF_T,MATCH($B5,GP_PF_Sectors,0),5),INDEX(GP_PF_T,MATCH($B5,GP_PF_Sectors,0),6),IF(Q5<=INDEX(GP_PF_T,MATCH($B5,GP_PF_Sectors,0),7),INDEX(GP_PF_T,MATCH($B5,GP_PF_Sectors,0),8),IF(Q5<=INDEX(GP_PF_T,MATCH($B5,GP_PF_Sectors,0),9),INDEX(GP_PF_T,MATCH($B5,GP_PF_Sectors,0),10),IF(Q5<=INDEX(GP_PF_T,MATCH($B5,GP_PF_Sectors,0),11),INDEX(GP_PF_T,MATCH($B5,GP_PF_Sectors,0),12),0)))))))) -> 82 | AJ5: =IF(OR($B5="",R5=""),"",IF(ISERROR(MATCH($B5,GP_DY_Sectors,0)),0,IF(R5>=INDEX(GP_DY_T,MATCH($B5,GP_DY_Sectors,0),1),INDEX(GP_DY_T,MATCH($B5,GP_DY_Sectors,0),2),IF(R5>=INDEX(GP_DY_T,MATCH($B5,GP_DY_Sectors,0),3),INDEX(GP_DY_T,MATCH($B5,GP_DY_Sectors,0),4),IF(R5>=INDEX(GP_DY_T,MATCH($B5,GP_DY_Sectors,0),5),INDEX(GP_DY_T,MATCH($B5,GP_DY_Sectors,0),6),IF(R5>=INDEX(GP_DY_T,MATCH($B5,GP_DY_Sectors,0),7),INDEX(GP_DY_T,MATCH($B5,GP_DY_Sectors,0),8),IF(R5>=INDEX(GP_DY_T,MATCH($B5,GP_DY_Sectors,0),9),INDEX(GP_DY_T,MATCH($B5,GP_DY_Sectors,0),10),IF(R5>=INDEX(GP_DY_T,MATCH($B5,GP_DY_Sectors,0),11),INDEX(GP_DY_T,MATCH($B5,GP_DY_Sectors,0),12),0)))))))) -> 100 | AK5: =IF(OR($B5="",S5=""),"",IF(ISERROR(MATCH($B5,GP_PR_Sectors,0)),0,IF(S5>=INDEX(GP_PR_T,MATCH($B5,GP_PR_Sectors,0),1),INDEX(GP_PR_T,MATCH($B5,GP_PR_Sectors,0),2),IF(S5>=INDEX(GP_PR_T,MATCH($B5,GP_PR_Sectors,0),3),INDEX(GP_PR_T,MATCH($B5,GP_PR_Sectors,0),4),IF(S5>=INDEX(GP_PR_T,MATCH($B5,GP_PR_Sectors,0),5),INDEX(GP_PR_T,MATCH($B5,GP_PR_Sectors,0),6),IF(S5>=INDEX(GP_PR_T,MATCH($B5,GP_PR_Sectors,0),7),INDEX(GP_PR_T,MATCH($B5,GP_PR_Sectors,0),8),IF(S5>=INDEX(GP_PR_T,MATCH($B5,GP_PR_Sectors,0),9),INDEX(GP_PR_T,MATCH($B5,GP_PR_Sectors,0),10),IF(S5>=INDEX(GP_PR_T,MATCH($B5,GP_PR_Sectors,0),11),INDEX(GP_PR_T,MATCH($B5,GP_PR_Sectors,0),12),0)))))))) -> 100 | AL5: =IF(OR($B5="",T5=""),"",IF(ISERROR(MATCH($B5,GP_BY_Sectors,0)),0,IF(T5>=INDEX(GP_BY_T,MATCH($B5,GP_BY_Sectors,0),1),INDEX(GP_BY_T,MATCH($B5,GP_BY_Sectors,0),2),IF(T5>=INDEX(GP_BY_T,MATCH($B5,GP_BY_Sectors,0),3),INDEX(GP_BY_T,MATCH($B5,GP_BY_Sectors,0),4),IF(T5>=INDEX(GP_BY_T,MATCH($B5,GP_BY_Sectors,0),5),INDEX(GP_BY_T,MATCH($B5,GP_BY_Sectors,0),6),IF(T5>=INDEX(GP_BY_T,MATCH($B5,GP_BY_Sectors,0),7),INDEX(GP_BY_T,MATCH($B5,GP_BY_Sectors,0),8),IF(T5>=INDEX(GP_BY_T,MATCH($B5,GP_BY_Sectors,0),9),INDEX(GP_BY_T,MATCH($B5,GP_BY_Sectors,0),10),IF(T5>=INDEX(GP_BY_T,MATCH($B5,GP_BY_Sectors,0),11),INDEX(GP_BY_T,MATCH($B5,GP_BY_Sectors,0),12),0)))))))) -> 68 | AM5: =IF($B5="","",U5*0.35+V5*0.35+W5*0.3) -> 88 | AN5: =IF($B5="","",X5*0.4+Y5*0.35+Z5*0.25) -> 39.25 | AO5: =IF($B5="","",AA5*0.35+AB5*0.3+AC5*0.35) -> 69.85 | AP5: =IF($B5="","",AD5*0.4+AE5*0.35+AF5*0.25) -> 79.75 | AQ5: =IF($B5="","",AG5*0.35+AH5*0.35+AI5*0.3) -> 82 | AR5: =IF($B5="","",AJ5*0.45+AK5*0.2+AL5*0.35) -> 88.8 | AS5: =IF($B5="","",MIN(100,MAX(0,ROUND(AM5*INDEX(GP_W_P1,MATCH($B5,GP_Weights_Sectors,0))+AN5*INDEX(GP_W_P2,MATCH($B5,GP_Weights_Sectors,0))+AO5*INDEX(GP_W_P3,MATCH($B5,GP_Weights_Sectors,0))+AP5*INDEX(GP_W_P4,MATCH($B5,GP_Weights_Sectors,0))+AQ5*INDEX(GP_W_P5,MATCH($B5,GP_Weights_Sectors,0))+AR5*INDEX(GP_W_P6,MATCH($B5,GP_Weights_Sectors,0)),0)))) -> 73 | AT5: 1 | AU5: 2 | AV5: 2 | AW5: =MAX(-10,MIN(10,AT5+AU5+AV5)) -> 5 | AX5: #VALUE! | AY5: {=_FV(AX5,"PRECIO")} -> 239.24 | AZ5: 182 | BA5: =IFERROR(INDEX('DCF Simplified'!$Y$4:$Y$38,MATCH(A5,'DCF Simplified'!$A$4:$A$38,0)),"") -> 154.33163 | BB5: =IF(OR(AY5="",AZ5=""),"",(AZ5-AY5)/AY5) -> -0.23925765 | BD5: -0.02 | BE5: 48 | BF5: -0.05 | BG5: =IF(BD5>0.1,100,IF(BD5>0.05,80,IF(BD5>0,65,IF(BD5>-0.05,45,IF(BD5>-0.1,25,10))))) -> 45 | BH5: =IF(AND(BE5>=40,BE5<=60),70,IF(AND(BE5>60,BE5<=70),85,IF(BE5>70,50,IF(AND(BE5>=30,BE5<40),55,40)))) -> 70 | BI5: =IF(BF5>0.2,100,IF(BF5>0.1,80,IF(BF5>0,65,IF(BF5>-0.1,45,IF(BF5>-0.2,25,10))))) -> 45 | BJ5: =ROUND(BG5*0.4+BH5*0.25+BI5*0.35,1) -> 51.3 | BK5: =IF(OR(AS5="",AQ5="",BJ5=""),"",ROUND(AS5*0.4+MAX(15,MIN(90,AQ5))*0.2+BJ5*0.25+MIN(100,MAX(0,AW5*10))*0.15,0)) -> 66 | BL5: =IF(BK5="","",IF(BK5>=85,"🟢 STRONG",IF(BK5>=70,"🟡 FAVORABLE",IF(BK5>=55,"⚪ NEUTRAL",IF(BK5>=40,"🟠 WEAK","🔴 AVOID"))))) -> ⚪ NEUTRAL | BM5: =IF(BK5="","",IF(AND(BK5>=75,BJ5>=70,AW5>=6),"🚀 STRONG BUY",IF(AND(BK5>=65,BJ5>=55),"✅ BUY",IF(BK5>=55,"⚠️ HOLD",IF(OR(BK5<45,AND(BJ5<35,AW5<3)),"🔴 SELL","🟠 UNDERWEIGHT"))))) -> ⚠️ HOLD
A6: Exxon Mobil Corp | B6: Energy | C6: 0.18 | D6: 0.12 | E6: 0.1 | F6: 0.08 | G6: 0.05 | H6: 1.4 | I6: 0.8 | J6: 1.4 | K6: 6 | L6: 0.08 | M6: 0.85 | N6: 0.15 | O6: 9 | P6: 6 | Q6: 10 | R6: 0.035 | S6: 0.4 | T6: 0.04 | U6: =IF(OR($B6="",C6=""),"",IF(ISERROR(MATCH($B6,GP_ROE_Sectors,0)),0,IF(C6>=INDEX(GP_ROE_T,MATCH($B6,GP_ROE_Sectors,0),1),INDEX(GP_ROE_T,MATCH($B6,GP_ROE_Sectors,0),2),IF(C6>=INDEX(GP_ROE_T,MATCH($B6,GP_ROE_Sectors,0),3),INDEX(GP_ROE_T,MATCH($B6,GP_ROE_Sectors,0),4),IF(C6>=INDEX(GP_ROE_T,MATCH($B6,GP_ROE_Sectors,0),5),INDEX(GP_ROE_T,MATCH($B6,GP_ROE_Sectors,0),6),IF(C6>=INDEX(GP_ROE_T,MATCH($B6,GP_ROE_Sectors,0),7),INDEX(GP_ROE_T,MATCH($B6,GP_ROE_Sectors,0),8),IF(C6>=INDEX(GP_ROE_T,MATCH($B6,GP_ROE_Sectors,0),9),INDEX(GP_ROE_T,MATCH($B6,GP_ROE_Sectors,0),10),IF(C6>=INDEX(GP_ROE_T,MATCH($B6,GP_ROE_Sectors,0),11),INDEX(GP_ROE_T,MATCH($B6,GP_ROE_Sectors,0),12),0)))))))) -> 85 | V6: =IF(OR($B6="",D6=""),"",IF(ISERROR(MATCH($B6,GP_ROIC_Sectors,0)),0,IF(D6>=INDEX(GP_ROIC_T,MATCH($B6,GP_ROIC_Sectors,0),1),INDEX(GP_ROIC_T,MATCH($B6,GP_ROIC_Sectors,0),2),IF(D6>=INDEX(GP_ROIC_T,MATCH($B6,GP_ROIC_Sectors,0),3),INDEX(GP_ROIC_T,MATCH($B6,GP_ROIC_Sectors,0),4),IF(D6>=INDEX(GP_ROIC_T,MATCH($B6,GP_ROIC_Sectors,0),5),INDEX(GP_ROIC_T,MATCH($B6,GP_ROIC_Sectors,0),6),IF(D6>=INDEX(GP_ROIC_T,MATCH($B6,GP_ROIC_Sectors,0),7),INDEX(GP_ROIC_T,MATCH($B6,GP_ROIC_Sectors,0),8),IF(D6>=INDEX(GP_ROIC_T,MATCH($B6,GP_ROIC_Sectors,0),9),INDEX(GP_ROIC_T,MATCH($B6,GP_ROIC_Sectors,0),10),IF(D6>=INDEX(GP_ROIC_T,MATCH($B6,GP_ROIC_Sectors,0),11),INDEX(GP_ROIC_T,MATCH($B6,GP_ROIC_Sectors,0),12),0)))))))) -> 82 | W6: =IF(OR($B6="",E6=""),"",IF(ISERROR(MATCH($B6,GP_NM_Sectors,0)),0,IF(E6>=INDEX(GP_NM_T,MATCH($B6,GP_NM_Sectors,0),1),INDEX(GP_NM_T,MATCH($B6,GP_NM_Sectors,0),2),IF(E6>=INDEX(GP_NM_T,MATCH($B6,GP_NM_Sectors,0),3),INDEX(GP_NM_T,MATCH($B6,GP_NM_Sectors,0),4),IF(E6>=INDEX(GP_NM_T,MATCH($B6,GP_NM_Sectors,0),5),INDEX(GP_NM_T,MATCH($B6,GP_NM_Sectors,0),6),IF(E6>=INDEX(GP_NM_T,MATCH($B6,GP_NM_Sectors,0),7),INDEX(GP_NM_T,MATCH($B6,GP_NM_Sectors,0),8),IF(E6>=INDEX(GP_NM_T,MATCH($B6,GP_NM_Sectors,0),9),INDEX(GP_NM_T,MATCH($B6,GP_NM_Sectors,0),10),IF(E6>=INDEX(GP_NM_T,MATCH($B6,GP_NM_Sectors,0),11),INDEX(GP_NM_T,MATCH($B6,GP_NM_Sectors,0),12),0)))))))) -> 82 | X6: =IF(OR($B6="",F6=""),"",IF(ISERROR(MATCH($B6,GP_RG_Sectors,0)),0,IF(F6>=INDEX(GP_RG_T,MATCH($B6,GP_RG_Sectors,0),1),INDEX(GP_RG_T,MATCH($B6,GP_RG_Sectors,0),2),IF(F6>=INDEX(GP_RG_T,MATCH($B6,GP_RG_Sectors,0),3),INDEX(GP_RG_T,MATCH($B6,GP_RG_Sectors,0),4),IF(F6>=INDEX(GP_RG_T,MATCH($B6,GP_RG_Sectors,0),5),INDEX(GP_RG_T,MATCH($B6,GP_RG_Sectors,0),6),IF(F6>=INDEX(GP_RG_T,MATCH($B6,GP_RG_Sectors,0),7),INDEX(GP_RG_T,MATCH($B6,GP_RG_Sectors,0),8),IF(F6>=INDEX(GP_RG_T,MATCH($B6,GP_RG_Sectors,0),9),INDEX(GP_RG_T,MATCH($B6,GP_RG_Sectors,0),10),IF(F6>=INDEX(GP_RG_T,MATCH($B6,GP_RG_Sectors,0),11),INDEX(GP_RG_T,MATCH($B6,GP_RG_Sectors,0),12),0)))))))) -> 65 | Y6: =IF(OR($B6="",G6=""),"",IF(ISERROR(MATCH($B6,GP_EG_Sectors,0)),0,IF(G6>=INDEX(GP_EG_T,MATCH($B6,GP_EG_Sectors,0),1),INDEX(GP_EG_T,MATCH($B6,GP_EG_Sectors,0),2),IF(G6>=INDEX(GP_EG_T,MATCH($B6,GP_EG_Sectors,0),3),INDEX(GP_EG_T,MATCH($B6,GP_EG_Sectors,0),4),IF(G6>=INDEX(GP_EG_T,MATCH($B6,GP_EG_Sectors,0),5),INDEX(GP_EG_T,MATCH($B6,GP_EG_Sectors,0),6),IF(G6>=INDEX(GP_EG_T,MATCH($B6,GP_EG_Sectors,0),7),INDEX(GP_EG_T,MATCH($B6,GP_EG_Sectors,0),8),IF(G6>=INDEX(GP_EG_T,MATCH($B6,GP_EG_Sectors,0),9),INDEX(GP_EG_T,MATCH($B6,GP_EG_Sectors,0),10),IF(G6>=INDEX(GP_EG_T,MATCH($B6,GP_EG_Sectors,0),11),INDEX(GP_EG_T,MATCH($B6,GP_EG_Sectors,0),12),0)))))))) -> 42 | Z6: =IF(OR($B6="",H6=""),"",IF(ISERROR(MATCH($B6,GP_OL_Sectors,0)),0,IF(H6>=INDEX(GP_OL_T,MATCH($B6,GP_OL_Sectors,0),1),INDEX(GP_OL_T,MATCH($B6,GP_OL_Sectors,0),2),IF(H6>=INDEX(GP_OL_T,MATCH($B6,GP_OL_Sectors,0),3),INDEX(GP_OL_T,MATCH($B6,GP_OL_Sectors,0),4),IF(H6>=INDEX(GP_OL_T,MATCH($B6,GP_OL_Sectors,0),5),INDEX(GP_OL_T,MATCH($B6,GP_OL_Sectors,0),6),IF(H6>=INDEX(GP_OL_T,MATCH($B6,GP_OL_Sectors,0),7),INDEX(GP_OL_T,MATCH($B6,GP_OL_Sectors,0),8),IF(H6>=INDEX(GP_OL_T,MATCH($B6,GP_OL_Sectors,0),9),INDEX(GP_OL_T,MATCH($B6,GP_OL_Sectors,0),10),IF(H6>=INDEX(GP_OL_T,MATCH($B6,GP_OL_Sectors,0),11),INDEX(GP_OL_T,MATCH($B6,GP_OL_Sectors,0),12),0)))))))) -> 65 | AA6: =IF(OR($B6="",I6=""),"",IF(ISERROR(MATCH($B6,GP_ND_Sectors,0)),0,IF(I6<=INDEX(GP_ND_T,MATCH($B6,GP_ND_Sectors,0),1),INDEX(GP_ND_T,MATCH($B6,GP_ND_Sectors,0),2),IF(I6<=INDEX(GP_ND_T,MATCH($B6,GP_ND_Sectors,0),3),INDEX(GP_ND_T,MATCH($B6,GP_ND_Sectors,0),4),IF(I6<=INDEX(GP_ND_T,MATCH($B6,GP_ND_Sectors,0),5),INDEX(GP_ND_T,MATCH($B6,GP_ND_Sectors,0),6),IF(I6<=INDEX(GP_ND_T,MATCH($B6,GP_ND_Sectors,0),7),INDEX(GP_ND_T,MATCH($B6,GP_ND_Sectors,0),8),IF(I6<=INDEX(GP_ND_T,MATCH($B6,GP_ND_Sectors,0),9),INDEX(GP_ND_T,MATCH($B6,GP_ND_Sectors,0),10),IF(I6<=INDEX(GP_ND_T,MATCH($B6,GP_ND_Sectors,0),11),INDEX(GP_ND_T,MATCH($B6,GP_ND_Sectors,0),12),0)))))))) -> 82 | AB6: =IF(OR($B6="",J6=""),"",IF(ISERROR(MATCH($B6,GP_CR_Sectors,0)),0,IF(J6>=INDEX(GP_CR_T,MATCH($B6,GP_CR_Sectors,0),1),INDEX(GP_CR_T,MATCH($B6,GP_CR_Sectors,0),2),IF(J6>=INDEX(GP_CR_T,MATCH($B6,GP_CR_Sectors,0),3),INDEX(GP_CR_T,MATCH($B6,GP_CR_Sectors,0),4),IF(J6>=INDEX(GP_CR_T,MATCH($B6,GP_CR_Sectors,0),5),INDEX(GP_CR_T,MATCH($B6,GP_CR_Sectors,0),6),IF(J6>=INDEX(GP_CR_T,MATCH($B6,GP_CR_Sectors,0),7),INDEX(GP_CR_T,MATCH($B6,GP_CR_Sectors,0),8),IF(J6>=INDEX(GP_CR_T,MATCH($B6,GP_CR_Sectors,0),9),INDEX(GP_CR_T,MATCH($B6,GP_CR_Sectors,0),10),IF(J6>=INDEX(GP_CR_T,MATCH($B6,GP_CR_Sectors,0),11),INDEX(GP_CR_T,MATCH($B6,GP_CR_Sectors,0),12),0)))))))) -> 65 | AC6: =IF(OR($B6="",K6=""),"",IF(ISERROR(MATCH($B6,GP_IC_Sectors,0)),0,IF(K6>=INDEX(GP_IC_T,MATCH($B6,GP_IC_Sectors,0),1),INDEX(GP_IC_T,MATCH($B6,GP_IC_Sectors,0),2),IF(K6>=INDEX(GP_IC_T,MATCH($B6,GP_IC_Sectors,0),3),INDEX(GP_IC_T,MATCH($B6,GP_IC_Sectors,0),4),IF(K6>=INDEX(GP_IC_T,MATCH($B6,GP_IC_Sectors,0),5),INDEX(GP_IC_T,MATCH($B6,GP_IC_Sectors,0),6),IF(K6>=INDEX(GP_IC_T,MATCH($B6,GP_IC_Sectors,0),7),INDEX(GP_IC_T,MATCH($B6,GP_IC_Sectors,0),8),IF(K6>=INDEX(GP_IC_T,MATCH($B6,GP_IC_Sectors,0),9),INDEX(GP_IC_T,MATCH($B6,GP_IC_Sectors,0),10),IF(K6>=INDEX(GP_IC_T,MATCH($B6,GP_IC_Sectors,0),11),INDEX(GP_IC_T,MATCH($B6,GP_IC_Sectors,0),12),0)))))))) -> 80 | AD6: =IF(OR($B6="",L6=""),"",IF(ISERROR(MATCH($B6,GP_FM_Sectors,0)),0,IF(L6>=INDEX(GP_FM_T,MATCH($B6,GP_FM_Sectors,0),1),INDEX(GP_FM_T,MATCH($B6,GP_FM_Sectors,0),2),IF(L6>=INDEX(GP_FM_T,MATCH($B6,GP_FM_Sectors,0),3),INDEX(GP_FM_T,MATCH($B6,GP_FM_Sectors,0),4),IF(L6>=INDEX(GP_FM_T,MATCH($B6,GP_FM_Sectors,0),5),INDEX(GP_FM_T,MATCH($B6,GP_FM_Sectors,0),6),IF(L6>=INDEX(GP_FM_T,MATCH($B6,GP_FM_Sectors,0),7),INDEX(GP_FM_T,MATCH($B6,GP_FM_Sectors,0),8),IF(L6>=INDEX(GP_FM_T,MATCH($B6,GP_FM_Sectors,0),9),INDEX(GP_FM_T,MATCH($B6,GP_FM_Sectors,0),10),IF(L6>=INDEX(GP_FM_T,MATCH($B6,GP_FM_Sectors,0),11),INDEX(GP_FM_T,MATCH($B6,GP_FM_Sectors,0),12),0)))))))) -> 80 | AE6: =IF(OR($B6="",M6=""),"",IF(ISERROR(MATCH($B6,GP_FN_Sectors,0)),0,IF(M6>=INDEX(GP_FN_T,MATCH($B6,GP_FN_Sectors,0),1),INDEX(GP_FN_T,MATCH($B6,GP_FN_Sectors,0),2),IF(M6>=INDEX(GP_FN_T,MATCH($B6,GP_FN_Sectors,0),3),INDEX(GP_FN_T,MATCH($B6,GP_FN_Sectors,0),4),IF(M6>=INDEX(GP_FN_T,MATCH($B6,GP_FN_Sectors,0),5),INDEX(GP_FN_T,MATCH($B6,GP_FN_Sectors,0),6),IF(M6>=INDEX(GP_FN_T,MATCH($B6,GP_FN_Sectors,0),7),INDEX(GP_FN_T,MATCH($B6,GP_FN_Sectors,0),8),IF(M6>=INDEX(GP_FN_T,MATCH($B6,GP_FN_Sectors,0),9),INDEX(GP_FN_T,MATCH($B6,GP_FN_Sectors,0),10),IF(M6>=INDEX(GP_FN_T,MATCH($B6,GP_FN_Sectors,0),11),INDEX(GP_FN_T,MATCH($B6,GP_FN_Sectors,0),12),0)))))))) -> 80 | AF6: =IF(OR($B6="",N6=""),"",IF(ISERROR(MATCH($B6,GP_CX_Sectors,0)),0,IF(N6<=INDEX(GP_CX_T,MATCH($B6,GP_CX_Sectors,0),1),INDEX(GP_CX_T,MATCH($B6,GP_CX_Sectors,0),2),IF(N6<=INDEX(GP_CX_T,MATCH($B6,GP_CX_Sectors,0),3),INDEX(GP_CX_T,MATCH($B6,GP_CX_Sectors,0),4),IF(N6<=INDEX(GP_CX_T,MATCH($B6,GP_CX_Sectors,0),5),INDEX(GP_CX_T,MATCH($B6,GP_CX_Sectors,0),6),IF(N6<=INDEX(GP_CX_T,MATCH($B6,GP_CX_Sectors,0),7),INDEX(GP_CX_T,MATCH($B6,GP_CX_Sectors,0),8),IF(N6<=INDEX(GP_CX_T,MATCH($B6,GP_CX_Sectors,0),9),INDEX(GP_CX_T,MATCH($B6,GP_CX_Sectors,0),10),IF(N6<=INDEX(GP_CX_T,MATCH($B6,GP_CX_Sectors,0),11),INDEX(GP_CX_T,MATCH($B6,GP_CX_Sectors,0),12),0)))))))) -> 62 | AG6: =IF(OR($B6="",O6=""),"",IF(ISERROR(MATCH($B6,GP_PE_Sectors,0)),0,IF(O6<=INDEX(GP_PE_T,MATCH($B6,GP_PE_Sectors,0),1),INDEX(GP_PE_T,MATCH($B6,GP_PE_Sectors,0),2),IF(O6<=INDEX(GP_PE_T,MATCH($B6,GP_PE_Sectors,0),3),INDEX(GP_PE_T,MATCH($B6,GP_PE_Sectors,0),4),IF(O6<=INDEX(GP_PE_T,MATCH($B6,GP_PE_Sectors,0),5),INDEX(GP_PE_T,MATCH($B6,GP_PE_Sectors,0),6),IF(O6<=INDEX(GP_PE_T,MATCH($B6,GP_PE_Sectors,0),7),INDEX(GP_PE_T,MATCH($B6,GP_PE_Sectors,0),8),IF(O6<=INDEX(GP_PE_T,MATCH($B6,GP_PE_Sectors,0),9),INDEX(GP_PE_T,MATCH($B6,GP_PE_Sectors,0),10),IF(O6<=INDEX(GP_PE_T,MATCH($B6,GP_PE_Sectors,0),11),INDEX(GP_PE_T,MATCH($B6,GP_PE_Sectors,0),12),0)))))))) -> 82 | AH6: =IF(OR($B6="",P6=""),"",IF(ISERROR(MATCH($B6,GP_EV_Sectors,0)),0,IF(P6<=INDEX(GP_EV_T,MATCH($B6,GP_EV_Sectors,0),1),INDEX(GP_EV_T,MATCH($B6,GP_EV_Sectors,0),2),IF(P6<=INDEX(GP_EV_T,MATCH($B6,GP_EV_Sectors,0),3),INDEX(GP_EV_T,MATCH($B6,GP_EV_Sectors,0),4),IF(P6<=INDEX(GP_EV_T,MATCH($B6,GP_EV_Sectors,0),5),INDEX(GP_EV_T,MATCH($B6,GP_EV_Sectors,0),6),IF(P6<=INDEX(GP_EV_T,MATCH($B6,GP_EV_Sectors,0),7),INDEX(GP_EV_T,MATCH($B6,GP_EV_Sectors,0),8),IF(P6<=INDEX(GP_EV_T,MATCH($B6,GP_EV_Sectors,0),9),INDEX(GP_EV_T,MATCH($B6,GP_EV_Sectors,0),10),IF(P6<=INDEX(GP_EV_T,MATCH($B6,GP_EV_Sectors,0),11),INDEX(GP_EV_T,MATCH($B6,GP_EV_Sectors,0),12),0)))))))) -> 82 | AI6: =IF(OR($B6="",Q6=""),"",IF(ISERROR(MATCH($B6,GP_PF_Sectors,0)),0,IF(Q6<=INDEX(GP_PF_T,MATCH($B6,GP_PF_Sectors,0),1),INDEX(GP_PF_T,MATCH($B6,GP_PF_Sectors,0),2),IF(Q6<=INDEX(GP_PF_T,MATCH($B6,GP_PF_Sectors,0),3),INDEX(GP_PF_T,MATCH($B6,GP_PF_Sectors,0),4),IF(Q6<=INDEX(GP_PF_T,MATCH($B6,GP_PF_Sectors,0),5),INDEX(GP_PF_T,MATCH($B6,GP_PF_Sectors,0),6),IF(Q6<=INDEX(GP_PF_T,MATCH($B6,GP_PF_Sectors,0),7),INDEX(GP_PF_T,MATCH($B6,GP_PF_Sectors,0),8),IF(Q6<=INDEX(GP_PF_T,MATCH($B6,GP_PF_Sectors,0),9),INDEX(GP_PF_T,MATCH($B6,GP_PF_Sectors,0),10),IF(Q6<=INDEX(GP_PF_T,MATCH($B6,GP_PF_Sectors,0),11),INDEX(GP_PF_T,MATCH($B6,GP_PF_Sectors,0),12),0)))))))) -> 80 | AJ6: =IF(OR($B6="",R6=""),"",IF(ISERROR(MATCH($B6,GP_DY_Sectors,0)),0,IF(R6>=INDEX(GP_DY_T,MATCH($B6,GP_DY_Sectors,0),1),INDEX(GP_DY_T,MATCH($B6,GP_DY_Sectors,0),2),IF(R6>=INDEX(GP_DY_T,MATCH($B6,GP_DY_Sectors,0),3),INDEX(GP_DY_T,MATCH($B6,GP_DY_Sectors,0),4),IF(R6>=INDEX(GP_DY_T,MATCH($B6,GP_DY_Sectors,0),5),INDEX(GP_DY_T,MATCH($B6,GP_DY_Sectors,0),6),IF(R6>=INDEX(GP_DY_T,MATCH($B6,GP_DY_Sectors,0),7),INDEX(GP_DY_T,MATCH($B6,GP_DY_Sectors,0),8),IF(R6>=INDEX(GP_DY_T,MATCH($B6,GP_DY_Sectors,0),9),INDEX(GP_DY_T,MATCH($B6,GP_DY_Sectors,0),10),IF(R6>=INDEX(GP_DY_T,MATCH($B6,GP_DY_Sectors,0),11),INDEX(GP_DY_T,MATCH($B6,GP_DY_Sectors,0),12),0)))))))) -> 68 | AK6: =IF(OR($B6="",S6=""),"",IF(ISERROR(MATCH($B6,GP_PR_Sectors,0)),0,IF(S6>=INDEX(GP_PR_T,MATCH($B6,GP_PR_Sectors,0),1),INDEX(GP_PR_T,MATCH($B6,GP_PR_Sectors,0),2),IF(S6>=INDEX(GP_PR_T,MATCH($B6,GP_PR_Sectors,0),3),INDEX(GP_PR_T,MATCH($B6,GP_PR_Sectors,0),4),IF(S6>=INDEX(GP_PR_T,MATCH($B6,GP_PR_Sectors,0),5),INDEX(GP_PR_T,MATCH($B6,GP_PR_Sectors,0),6),IF(S6>=INDEX(GP_PR_T,MATCH($B6,GP_PR_Sectors,0),7),INDEX(GP_PR_T,MATCH($B6,GP_PR_Sectors,0),8),IF(S6>=INDEX(GP_PR_T,MATCH($B6,GP_PR_Sectors,0),9),INDEX(GP_PR_T,MATCH($B6,GP_PR_Sectors,0),10),IF(S6>=INDEX(GP_PR_T,MATCH($B6,GP_PR_Sectors,0),11),INDEX(GP_PR_T,MATCH($B6,GP_PR_Sectors,0),12),0)))))))) -> 100 | AL6: =IF(OR($B6="",T6=""),"",IF(ISERROR(MATCH($B6,GP_BY_Sectors,0)),0,IF(T6>=INDEX(GP_BY_T,MATCH($B6,GP_BY_Sectors,0),1),INDEX(GP_BY_T,MATCH($B6,GP_BY_Sectors,0),2),IF(T6>=INDEX(GP_BY_T,MATCH($B6,GP_BY_Sectors,0),3),INDEX(GP_BY_T,MATCH($B6,GP_BY_Sectors,0),4),IF(T6>=INDEX(GP_BY_T,MATCH($B6,GP_BY_Sectors,0),5),INDEX(GP_BY_T,MATCH($B6,GP_BY_Sectors,0),6),IF(T6>=INDEX(GP_BY_T,MATCH($B6,GP_BY_Sectors,0),7),INDEX(GP_BY_T,MATCH($B6,GP_BY_Sectors,0),8),IF(T6>=INDEX(GP_BY_T,MATCH($B6,GP_BY_Sectors,0),9),INDEX(GP_BY_T,MATCH($B6,GP_BY_Sectors,0),10),IF(T6>=INDEX(GP_BY_T,MATCH($B6,GP_BY_Sectors,0),11),INDEX(GP_BY_T,MATCH($B6,GP_BY_Sectors,0),12),0)))))))) -> 80 | AM6: =IF($B6="","",U6*0.35+V6*0.35+W6*0.3) -> 83.05 | AN6: =IF($B6="","",X6*0.4+Y6*0.35+Z6*0.25) -> 56.95 | AO6: =IF($B6="","",AA6*0.35+AB6*0.3+AC6*0.35) -> 76.2 | AP6: =IF($B6="","",AD6*0.4+AE6*0.35+AF6*0.25) -> 75.5 | AQ6: =IF($B6="","",AG6*0.35+AH6*0.35+AI6*0.3) -> 81.4 | AR6: =IF($B6="","",AJ6*0.45+AK6*0.2+AL6*0.35) -> 78.6 | AS6: =IF($B6="","",MIN(100,MAX(0,ROUND(AM6*INDEX(GP_W_P1,MATCH($B6,GP_Weights_Sectors,0))+AN6*INDEX(GP_W_P2,MATCH($B6,GP_Weights_Sectors,0))+AO6*INDEX(GP_W_P3,MATCH($B6,GP_Weights_Sectors,0))+AP6*INDEX(GP_W_P4,MATCH($B6,GP_Weights_Sectors,0))+AQ6*INDEX(GP_W_P5,MATCH($B6,GP_Weights_Sectors,0))+AR6*INDEX(GP_W_P6,MATCH($B6,GP_Weights_Sectors,0)),0)))) -> 75 | AT6: 1 | AU6: 2 | AV6: 3 | AW6: =MAX(-10,MIN(10,AT6+AU6+AV6)) -> 6 | AX6: #VALUE! | AY6: {=_FV(AX6,"PRECIO")} -> 165.43 | AZ6: 142 | BA6: =IFERROR(INDEX('DCF Simplified'!$Y$4:$Y$38,MATCH(A6,'DCF Simplified'!$A$4:$A$38,0)),"") -> 128.95781 | BB6: =IF(OR(AY6="",AZ6=""),"",(AZ6-AY6)/AY6) -> -0.1416309 | BD6: -0.05 | BE6: 44 | BF6: -0.12 | BG6: =IF(BD6>0.1,100,IF(BD6>0.05,80,IF(BD6>0,65,IF(BD6>-0.05,45,IF(BD6>-0.1,25,10))))) -> 25 | BH6: =IF(AND(BE6>=40,BE6<=60),70,IF(AND(BE6>60,BE6<=70),85,IF(BE6>70,50,IF(AND(BE6>=30,BE6<40),55,40)))) -> 70 | BI6: =IF(BF6>0.2,100,IF(BF6>0.1,80,IF(BF6>0,65,IF(BF6>-0.1,45,IF(BF6>-0.2,25,10))))) -> 25 | BJ6: =ROUND(BG6*0.4+BH6*0.25+BI6*0.35,1) -> 36.3 | BK6: =IF(OR(AS6="",AQ6="",BJ6=""),"",ROUND(AS6*0.4+MAX(15,MIN(90,AQ6))*0.2+BJ6*0.25+MIN(100,MAX(0,AW6*10))*0.15,0)) -> 64 | BL6: =IF(BK6="","",IF(BK6>=85,"🟢 STRONG",IF(BK6>=70,"🟡 FAVORABLE",IF(BK6>=55,"⚪ NEUTRAL",IF(BK6>=40,"🟠 WEAK","🔴 AVOID"))))) -> ⚪ NEUTRAL | BM6: =IF(BK6="","",IF(AND(BK6>=75,BJ6>=70,AW6>=6),"🚀 STRONG BUY",IF(AND(BK6>=65,BJ6>=55),"✅ BUY",IF(BK6>=55,"⚠️ HOLD",IF(OR(BK6<45,AND(BJ6<35,AW6<3)),"🔴 SELL","🟠 UNDERWEIGHT"))))) -> ⚠️ HOLD
